[2023-08-17T07:23:21.000+0000] {taskinstance.py:1103} INFO - Dependencies all met for dep_context=non-requeueable deps ti=<TaskInstance: data_cleaning_dag.load_data manual__2023-08-17T07:23:14.151262+00:00 [queued]>
[2023-08-17T07:23:21.058+0000] {taskinstance.py:1103} INFO - Dependencies all met for dep_context=requeueable deps ti=<TaskInstance: data_cleaning_dag.load_data manual__2023-08-17T07:23:14.151262+00:00 [queued]>
[2023-08-17T07:23:21.061+0000] {taskinstance.py:1308} INFO - Starting attempt 1 of 1
[2023-08-17T07:23:21.079+0000] {taskinstance.py:1327} INFO - Executing <Task(PythonOperator): load_data> on 2023-08-17 07:23:14.151262+00:00
[2023-08-17T07:23:21.117+0000] {standard_task_runner.py:57} INFO - Started process 4973 to run task
[2023-08-17T07:23:21.138+0000] {standard_task_runner.py:84} INFO - Running: ['***', 'tasks', 'run', 'data_cleaning_dag', 'load_data', 'manual__2023-08-17T07:23:14.151262+00:00', '--job-id', '409', '--raw', '--subdir', 'DAGS_FOLDER/data_cleaning_dag/data_cleaning.py', '--cfg-path', '/tmp/tmp0__k33tl']
[2023-08-17T07:23:21.141+0000] {standard_task_runner.py:85} INFO - Job 409: Subtask load_data
[2023-08-17T07:23:21.209+0000] {task_command.py:410} INFO - Running <TaskInstance: data_cleaning_dag.load_data manual__2023-08-17T07:23:14.151262+00:00 [running]> on host 77a7d2857de0
[2023-08-17T07:23:21.321+0000] {taskinstance.py:1547} INFO - Exporting env vars: AIRFLOW_CTX_DAG_OWNER='***' AIRFLOW_CTX_DAG_ID='data_cleaning_dag' AIRFLOW_CTX_TASK_ID='load_data' AIRFLOW_CTX_EXECUTION_DATE='2023-08-17T07:23:14.151262+00:00' AIRFLOW_CTX_TRY_NUMBER='1' AIRFLOW_CTX_DAG_RUN_ID='manual__2023-08-17T07:23:14.151262+00:00'
[2023-08-17T07:23:21.331+0000] {taskinstance.py:1824} ERROR - Task failed with exception
Traceback (most recent call last):
  File "/home/airflow/.local/lib/python3.7/site-packages/airflow/operators/python.py", line 181, in execute
    return_value = self.execute_callable()
  File "/home/airflow/.local/lib/python3.7/site-packages/airflow/operators/python.py", line 198, in execute_callable
    return self.python_callable(*self.op_args, **self.op_kwargs)
  File "/opt/airflow/dags/data_cleaning_dag/data_cleaning.py", line 41, in load_data
    processed_data_path = os.path.join(dag_folder, 'processed_data/hotel_booking_portugal_data.csv')
NameError: name 'dag_folder' is not defined
[2023-08-17T07:23:21.355+0000] {taskinstance.py:1350} INFO - Marking task as FAILED. dag_id=data_cleaning_dag, task_id=load_data, execution_date=20230817T072314, start_date=20230817T072321, end_date=20230817T072321
[2023-08-17T07:23:21.371+0000] {standard_task_runner.py:109} ERROR - Failed to execute job 409 for task load_data (name 'dag_folder' is not defined; 4973)
[2023-08-17T07:23:21.392+0000] {local_task_job_runner.py:225} INFO - Task exited with return code 1
[2023-08-17T07:23:21.417+0000] {taskinstance.py:2653} INFO - 0 downstream tasks scheduled from follow-on schedule check
