[2023-08-15T10:06:07.283+0000] {taskinstance.py:1103} INFO - Dependencies all met for dep_context=non-requeueable deps ti=<TaskInstance: data_cleaning_dag.data_cleaning manual__2023-08-15T10:06:03.907569+00:00 [queued]>
[2023-08-15T10:06:07.289+0000] {taskinstance.py:1103} INFO - Dependencies all met for dep_context=requeueable deps ti=<TaskInstance: data_cleaning_dag.data_cleaning manual__2023-08-15T10:06:03.907569+00:00 [queued]>
[2023-08-15T10:06:07.289+0000] {taskinstance.py:1308} INFO - Starting attempt 1 of 1
[2023-08-15T10:06:07.299+0000] {taskinstance.py:1327} INFO - Executing <Task(PythonOperator): data_cleaning> on 2023-08-15 10:06:03.907569+00:00
[2023-08-15T10:06:07.304+0000] {standard_task_runner.py:57} INFO - Started process 27149 to run task
[2023-08-15T10:06:07.308+0000] {standard_task_runner.py:84} INFO - Running: ['***', 'tasks', 'run', 'data_cleaning_dag', 'data_cleaning', 'manual__2023-08-15T10:06:03.907569+00:00', '--job-id', '370', '--raw', '--subdir', 'DAGS_FOLDER/data_cleaning_dag/data_cleaning.py', '--cfg-path', '/tmp/tmpgifjbw3k']
[2023-08-15T10:06:07.309+0000] {standard_task_runner.py:85} INFO - Job 370: Subtask data_cleaning
[2023-08-15T10:06:07.357+0000] {task_command.py:410} INFO - Running <TaskInstance: data_cleaning_dag.data_cleaning manual__2023-08-15T10:06:03.907569+00:00 [running]> on host 77a7d2857de0
[2023-08-15T10:06:07.442+0000] {taskinstance.py:1547} INFO - Exporting env vars: AIRFLOW_CTX_DAG_OWNER='***' AIRFLOW_CTX_DAG_ID='data_cleaning_dag' AIRFLOW_CTX_TASK_ID='data_cleaning' AIRFLOW_CTX_EXECUTION_DATE='2023-08-15T10:06:03.907569+00:00' AIRFLOW_CTX_TRY_NUMBER='1' AIRFLOW_CTX_DAG_RUN_ID='manual__2023-08-15T10:06:03.907569+00:00'
[2023-08-15T10:06:07.449+0000] {taskinstance.py:1824} ERROR - Task failed with exception
Traceback (most recent call last):
  File "/home/airflow/.local/lib/python3.7/site-packages/airflow/operators/python.py", line 181, in execute
    return_value = self.execute_callable()
  File "/home/airflow/.local/lib/python3.7/site-packages/airflow/operators/python.py", line 198, in execute_callable
    return self.python_callable(*self.op_args, **self.op_kwargs)
  File "/opt/airflow/dags/data_cleaning_dag/data_cleaning.py", line 14, in data_cleaning
    hotel_data = pd.read_csv('raw_data/hotel_booking_portugal_data.csv')
  File "/home/airflow/.local/lib/python3.7/site-packages/pandas/util/_decorators.py", line 311, in wrapper
    return func(*args, **kwargs)
  File "/home/airflow/.local/lib/python3.7/site-packages/pandas/io/parsers/readers.py", line 586, in read_csv
    return _read(filepath_or_buffer, kwds)
  File "/home/airflow/.local/lib/python3.7/site-packages/pandas/io/parsers/readers.py", line 482, in _read
    parser = TextFileReader(filepath_or_buffer, **kwds)
  File "/home/airflow/.local/lib/python3.7/site-packages/pandas/io/parsers/readers.py", line 811, in __init__
    self._engine = self._make_engine(self.engine)
  File "/home/airflow/.local/lib/python3.7/site-packages/pandas/io/parsers/readers.py", line 1040, in _make_engine
    return mapping[engine](self.f, **self.options)  # type: ignore[call-arg]
  File "/home/airflow/.local/lib/python3.7/site-packages/pandas/io/parsers/c_parser_wrapper.py", line 51, in __init__
    self._open_handles(src, kwds)
  File "/home/airflow/.local/lib/python3.7/site-packages/pandas/io/parsers/base_parser.py", line 229, in _open_handles
    errors=kwds.get("encoding_errors", "strict"),
  File "/home/airflow/.local/lib/python3.7/site-packages/pandas/io/common.py", line 707, in get_handle
    newline="",
FileNotFoundError: [Errno 2] No such file or directory: 'raw_data/hotel_booking_portugal_data.csv'
[2023-08-15T10:06:07.463+0000] {taskinstance.py:1350} INFO - Marking task as FAILED. dag_id=data_cleaning_dag, task_id=data_cleaning, execution_date=20230815T100603, start_date=20230815T100607, end_date=20230815T100607
[2023-08-15T10:06:07.472+0000] {standard_task_runner.py:109} ERROR - Failed to execute job 370 for task data_cleaning ([Errno 2] No such file or directory: 'raw_data/hotel_booking_portugal_data.csv'; 27149)
[2023-08-15T10:06:07.480+0000] {local_task_job_runner.py:225} INFO - Task exited with return code 1
[2023-08-15T10:06:07.499+0000] {taskinstance.py:2653} INFO - 0 downstream tasks scheduled from follow-on schedule check
