[2023-08-15T11:43:51.888+0000] {taskinstance.py:1103} INFO - Dependencies all met for dep_context=non-requeueable deps ti=<TaskInstance: data_cleaning_dag.data_cleaning manual__2023-08-15T11:43:48.731708+00:00 [queued]>
[2023-08-15T11:43:51.894+0000] {taskinstance.py:1103} INFO - Dependencies all met for dep_context=requeueable deps ti=<TaskInstance: data_cleaning_dag.data_cleaning manual__2023-08-15T11:43:48.731708+00:00 [queued]>
[2023-08-15T11:43:51.895+0000] {taskinstance.py:1308} INFO - Starting attempt 1 of 1
[2023-08-15T11:43:51.906+0000] {taskinstance.py:1327} INFO - Executing <Task(PythonOperator): data_cleaning> on 2023-08-15 11:43:48.731708+00:00
[2023-08-15T11:43:51.914+0000] {standard_task_runner.py:57} INFO - Started process 60211 to run task
[2023-08-15T11:43:51.917+0000] {standard_task_runner.py:84} INFO - Running: ['***', 'tasks', 'run', 'data_cleaning_dag', 'data_cleaning', 'manual__2023-08-15T11:43:48.731708+00:00', '--job-id', '378', '--raw', '--subdir', 'DAGS_FOLDER/data_cleaning_dag/data_cleaning.py', '--cfg-path', '/tmp/tmpm55i2jgx']
[2023-08-15T11:43:51.919+0000] {standard_task_runner.py:85} INFO - Job 378: Subtask data_cleaning
[2023-08-15T11:43:52.002+0000] {task_command.py:410} INFO - Running <TaskInstance: data_cleaning_dag.data_cleaning manual__2023-08-15T11:43:48.731708+00:00 [running]> on host 77a7d2857de0
[2023-08-15T11:43:52.105+0000] {taskinstance.py:1547} INFO - Exporting env vars: AIRFLOW_CTX_DAG_OWNER='***' AIRFLOW_CTX_DAG_ID='data_cleaning_dag' AIRFLOW_CTX_TASK_ID='data_cleaning' AIRFLOW_CTX_EXECUTION_DATE='2023-08-15T11:43:48.731708+00:00' AIRFLOW_CTX_TRY_NUMBER='1' AIRFLOW_CTX_DAG_RUN_ID='manual__2023-08-15T11:43:48.731708+00:00'
[2023-08-15T11:43:52.113+0000] {taskinstance.py:1824} ERROR - Task failed with exception
Traceback (most recent call last):
  File "/home/airflow/.local/lib/python3.7/site-packages/airflow/operators/python.py", line 181, in execute
    return_value = self.execute_callable()
  File "/home/airflow/.local/lib/python3.7/site-packages/airflow/operators/python.py", line 198, in execute_callable
    return self.python_callable(*self.op_args, **self.op_kwargs)
  File "/opt/airflow/dags/data_cleaning_dag/data_cleaning.py", line 17, in data_cleaning
    hotel_data.head() # First row
AttributeError: 'str' object has no attribute 'head'
[2023-08-15T11:43:52.137+0000] {taskinstance.py:1350} INFO - Marking task as FAILED. dag_id=data_cleaning_dag, task_id=data_cleaning, execution_date=20230815T114348, start_date=20230815T114351, end_date=20230815T114352
[2023-08-15T11:43:52.151+0000] {standard_task_runner.py:109} ERROR - Failed to execute job 378 for task data_cleaning ('str' object has no attribute 'head'; 60211)
[2023-08-15T11:43:52.172+0000] {local_task_job_runner.py:225} INFO - Task exited with return code 1
[2023-08-15T11:43:52.192+0000] {taskinstance.py:2653} INFO - 0 downstream tasks scheduled from follow-on schedule check
