[2023-08-17T07:25:40.816+0000] {taskinstance.py:1103} INFO - Dependencies all met for dep_context=non-requeueable deps ti=<TaskInstance: data_cleaning_dag.load_data manual__2023-08-17T07:25:34.348573+00:00 [queued]>
[2023-08-17T07:25:40.822+0000] {taskinstance.py:1103} INFO - Dependencies all met for dep_context=requeueable deps ti=<TaskInstance: data_cleaning_dag.load_data manual__2023-08-17T07:25:34.348573+00:00 [queued]>
[2023-08-17T07:25:40.823+0000] {taskinstance.py:1308} INFO - Starting attempt 1 of 1
[2023-08-17T07:25:40.832+0000] {taskinstance.py:1327} INFO - Executing <Task(PythonOperator): load_data> on 2023-08-17 07:25:34.348573+00:00
[2023-08-17T07:25:40.840+0000] {standard_task_runner.py:57} INFO - Started process 6334 to run task
[2023-08-17T07:25:40.845+0000] {standard_task_runner.py:84} INFO - Running: ['***', 'tasks', 'run', 'data_cleaning_dag', 'load_data', 'manual__2023-08-17T07:25:34.348573+00:00', '--job-id', '415', '--raw', '--subdir', 'DAGS_FOLDER/data_cleaning_dag/data_cleaning.py', '--cfg-path', '/tmp/tmpic7_8ld1']
[2023-08-17T07:25:40.847+0000] {standard_task_runner.py:85} INFO - Job 415: Subtask load_data
[2023-08-17T07:25:40.919+0000] {task_command.py:410} INFO - Running <TaskInstance: data_cleaning_dag.load_data manual__2023-08-17T07:25:34.348573+00:00 [running]> on host 77a7d2857de0
[2023-08-17T07:25:41.043+0000] {taskinstance.py:1547} INFO - Exporting env vars: AIRFLOW_CTX_DAG_OWNER='***' AIRFLOW_CTX_DAG_ID='data_cleaning_dag' AIRFLOW_CTX_TASK_ID='load_data' AIRFLOW_CTX_EXECUTION_DATE='2023-08-17T07:25:34.348573+00:00' AIRFLOW_CTX_TRY_NUMBER='1' AIRFLOW_CTX_DAG_RUN_ID='manual__2023-08-17T07:25:34.348573+00:00'
[2023-08-17T07:25:41.048+0000] {taskinstance.py:1824} ERROR - Task failed with exception
Traceback (most recent call last):
  File "/home/airflow/.local/lib/python3.7/site-packages/airflow/operators/python.py", line 181, in execute
    return_value = self.execute_callable()
  File "/home/airflow/.local/lib/python3.7/site-packages/airflow/operators/python.py", line 198, in execute_callable
    return self.python_callable(*self.op_args, **self.op_kwargs)
  File "/opt/airflow/dags/data_cleaning_dag/data_cleaning.py", line 40, in load_data
    cleaned_data = cleaned_data
UnboundLocalError: local variable 'cleaned_data' referenced before assignment
[2023-08-17T07:25:41.057+0000] {taskinstance.py:1350} INFO - Marking task as FAILED. dag_id=data_cleaning_dag, task_id=load_data, execution_date=20230817T072534, start_date=20230817T072540, end_date=20230817T072541
[2023-08-17T07:25:41.064+0000] {standard_task_runner.py:109} ERROR - Failed to execute job 415 for task load_data (local variable 'cleaned_data' referenced before assignment; 6334)
[2023-08-17T07:25:41.102+0000] {local_task_job_runner.py:225} INFO - Task exited with return code 1
[2023-08-17T07:25:41.121+0000] {taskinstance.py:2653} INFO - 0 downstream tasks scheduled from follow-on schedule check
